2018-03-13 22:25:56,594 - ERROR - spider.py[:143] - (pymysql.err.InternalError) (1292, "Incorrect datetime value: '计划到达时间' for column 'ArriveTime' at row 1") [SQL: 'UPDATE user SET `ArriveTime`=%(ArriveTime)s WHERE user.`CarId` = %(user_CarId)s'] [parameters: {'ArriveTime': '计划到达时间', 'user_CarId': '浙APY123'}] (Background on this error at: http://sqlalche.me/e/2j85)
2018-03-13 22:29:30,737 - ERROR - spider.py[:145] - (pymysql.err.InternalError) (1292, "Incorrect datetime value: '计划到达时间' for column 'ArriveTime' at row 1") [SQL: 'UPDATE user SET `ArriveTime`=%(ArriveTime)s WHERE user.`CarId` = %(user_CarId)s'] [parameters: {'ArriveTime': '计划到达时间', 'user_CarId': '浙APY123'}] (Background on this error at: http://sqlalche.me/e/2j85)
2018-03-14 10:06:10,896 - ERROR - spider.py[:159] - (pymysql.err.InternalError) (1292, "Incorrect datetime value: '计划到达时间' for column 'ArriveTime' at row 1") [SQL: 'UPDATE user SET `ArriveTime`=%(ArriveTime)s WHERE user.`CarId` = %(user_CarId)s'] [parameters: {'ArriveTime': '计划到达时间', 'user_CarId': '浙APY123'}] (Background on this error at: http://sqlalche.me/e/2j85)
2018-03-14 10:10:26,522 - ERROR - spider.py[:159] - (pymysql.err.InternalError) (1292, "Incorrect datetime value: '计划到达时间' for column 'ArriveTime' at row 1") [SQL: 'UPDATE user SET `ArriveTime`=%(ArriveTime)s WHERE user.`CarId` = %(user_CarId)s'] [parameters: {'ArriveTime': '计划到达时间', 'user_CarId': '浙APY123'}] (Background on this error at: http://sqlalche.me/e/2j85)
2018-03-14 10:11:14,815 - ERROR - spider.py[:159] - (pymysql.err.InternalError) (1292, "Incorrect datetime value: '计划到达时间' for column 'ArriveTime' at row 1") [SQL: 'UPDATE user SET `ArriveTime`=%(ArriveTime)s WHERE user.`CarId` = %(user_CarId)s'] [parameters: {'ArriveTime': '计划到达时间', 'user_CarId': '浙APY123'}] (Background on this error at: http://sqlalche.me/e/2j85)
2018-03-14 10:12:07,051 - ERROR - spider.py[:159] - (pymysql.err.InternalError) (1292, "Incorrect datetime value: '计划到达时间' for column 'ArriveTime' at row 1") [SQL: 'UPDATE user SET `ArriveTime`=%(ArriveTime)s WHERE user.`CarId` = %(user_CarId)s'] [parameters: {'ArriveTime': '计划到达时间', 'user_CarId': '浙APY123'}] (Background on this error at: http://sqlalche.me/e/2j85)
2018-03-14 10:13:24,997 - ERROR - spider.py[:160] - (pymysql.err.InternalError) (1292, "Incorrect datetime value: '计划到达时间' for column 'ArriveTime' at row 1") [SQL: 'UPDATE user SET `ArriveTime`=%(ArriveTime)s WHERE user.`CarId` = %(user_CarId)s'] [parameters: {'ArriveTime': '计划到达时间', 'user_CarId': '浙APY123'}] (Background on this error at: http://sqlalche.me/e/2j85)
2018-03-14 11:17:09,795 - ERROR - spider.py[:160] - (pymysql.err.OperationalError) (2013, 'Lost connection to MySQL server during query ([WinError 10060] 由于连接方在一段时间后没有正确答复或连接的主机没有反应，连接尝试失败。)') [SQL: 'SELECT user.`CarId` AS `user_CarId`, user.`FlightNum` AS `user_FlightNum`, user.`FlyDate` AS `user_FlyDate`, user.`ArriveTime` AS `user_ArriveTime`, user.`ParkDate` AS `user_ParkDate`, user.`Phone` AS `user_Phone`, user.`ParkPlace` AS `user_ParkPlace`, user.`BackPersons` AS `user_BackPersons`, user.`BoxNum` AS `user_BoxNum`, user.`Fee` AS `user_Fee` \nFROM user \nWHERE user.`FlightNum` = %(FlightNum_1)s'] [parameters: {'FlightNum_1': 'HU7607'}] (Background on this error at: http://sqlalche.me/e/e3q8)
